<?xml version="1.0"?>
<robot name="platform">
  <link name="platform_base_link">
    <contact>
      <lateral_friction value="1.0"/>
      <spinning_friction value=".001"/>
    </contact>
    <inertial>
      <origin rpy="0 0 0" xyz="0 0 0"/>
      <mass value="0.02"/>
      <inertia ixx="0.00167" ixy="0" ixz="0" iyy="0.00167" iyz="0" izz="0.00333"/>
    </inertial>
    <visual>
      <origin rpy="0 0 0" xyz="0.0 0.0 0.0"/>
      <geometry>
        <box size="1.0 1.0 0.018"/>
      </geometry>
      <material name="blockmat">
        <color rgba="0.1 0.7 0.1 1"/>
      </material>
    </visual>
    <collision>
      <origin rpy="0 0 0" xyz="0.0 0.0 0.0"/>
      <geometry>
        <box size="1.0 1.0 0.018"/>
      </geometry>
    </collision>
  </link>

  <link name="world"/>
  <joint name="world_joint" type="prismatic">
    <parent link="world"/>
    <child link="platform_base_link"/>
    <origin rpy="0.0 0.0 0.0" xyz="0.0 0.0 0.0"/>
    <axis xyz="0 0 1"/>
    <limit lower="0.0" upper="1.0" effort="100.0" velocity="0.5"/>
    <dynamics damping="0.1" friction="0.1"/>
  </joint>
</robot>
